<?xml version="1.0" encoding="utf-8"?>
<!-- This URDF was automatically created by SolidWorks to URDF Exporter! Originally created by Stephen Brawner (brawner@gmail.com)
     Commit Version: 1.6.0-1-g15f4949  Build Version: 1.6.7594.29634
     For more information, please see http://wiki.ros.org/sw_urdf_exporter -->

<robot name="rider_description">

  <!-- initial color -->
  <material name="black">
    <color rgba="0.0 0.0 0.0 1.0" />
  </material>

  <material name="grey">
    <color rgba="0.5 0.5 0.5 1.0" />
  </material>

  <material name="white">
    <color rgba="1.0 1.0 1.0 1.0" />
  </material>

  <!-- components -->
  <link name="base_footprint" />

  <link name="base_link">
    <inertial>
      <origin xyz="0.00328 -0.00025605 0.051183" rpy="0 0 0" />
      <mass value="0.71871" />
      <inertia ixx="0.00082013" ixy="7.2515E-06" ixz="-6.9474E-07" iyy="0.00084436" iyz="-2.068E-09" izz="0.0016324" />
    </inertial>
    <visual>
      <origin xyz="-0.032 0 0" rpy="0 0 0" />
      <geometry>
        <mesh filename="package://rider_description/meshes/base_link.STL" />
      </geometry>
      <material name="white"/>
    </visual>
    <collision>
      <origin xyz="-0.032 0 0.0615" rpy="0 0 0" />
      <geometry>
        <!-- <mesh filename="package://rider_description/meshes/base_link.STL" /> -->
        <box size="0.1418 0.1418 0.123"/>
      </geometry>
    </collision>
  </link>

  <joint name="base_joint" type="fixed">
    <origin xyz="0.0 0.0 0.010" rpy="0.0 0.0 0.0"/>
    <parent link="base_footprint"/>
    <child link="base_link"/>
  </joint>

  <link name="wheel_left_link">
    <inertial>
      <origin xyz="-8.9269E-08 -0.00070395 -1.7385E-06" rpy="0 0 0" />
      <mass value="0.026086" />
      <inertia ixx="1.0117E-05" ixy="-5.2556E-09" ixz="-1.4482E-10" iyy="1.8804E-05" iyz="1.2763E-11" izz="1.0129E-05" />
    </inertial>
    <visual>
      <origin xyz="0 0 0" rpy="0 0 0" />
      <geometry>
        <mesh filename="package://rider_description/meshes/wheel_left_link.STL" />
      </geometry>
      <material name="black"/>
    </visual>
    <collision>
      <origin xyz="0 0 0" rpy="1.57 0 0" />
      <geometry>
        <!-- <mesh filename="package://rider_description/meshes/wheel_left_link.STL" /> -->
        <cylinder radius="0.033" length="0.018"/>
      </geometry>
    </collision>
  </link>

  <joint name="wheel_left_joint" type="continuous">
    <origin xyz="0 0.0799 0.02325" rpy="0 0 0" />
    <parent link="base_link" />
    <child link="wheel_left_link" />
    <axis xyz="0 1 0" />
  </joint>

  <link name="wheel_right_link">
    <inertial>
      <origin xyz="8.9269E-08 0.00070395 -1.7385E-06" rpy="0 0 0" />
      <mass value="0.026086" />
      <inertia ixx="1.0117E-05" ixy="-5.2556E-09" ixz="1.4482E-10" iyy="1.8804E-05" iyz="-1.2763E-11" izz="1.0129E-05" />
    </inertial>
    <visual>
      <origin xyz="0 0 0" rpy="0 0 0" />
      <geometry>
        <mesh filename="package://rider_description/meshes/wheel_right_link.STL" />
      </geometry>
      <material name="black"/>
    </visual>
    <collision>
      <origin xyz="0 0 0" rpy="1.57 0 0" />
      <geometry>
        <!-- <mesh filename="package://rider_description/meshes/wheel_right_link.STL" /> -->
        <cylinder radius="0.033" length="0.018"/>
      </geometry>
    </collision>
  </link>

  <joint name="wheel_right_joint" type="continuous">
    <origin xyz="0 -0.0799 0.02325" rpy="0 0 0" />
    <parent link="base_link" />
    <child link="wheel_right_link" />
    <axis xyz="0 1 0" />
  </joint>

  <link name="caster_link">
    <inertial>
      <origin xyz="0.0 0.0 0.0" rpy="0.0 0.0 0.0"/>
      <mass value="0.005"/>
      <inertia ixx="0.001" ixy="0.0" ixz="0.0" iyy="0.001" iyz="0.0" izz="0.001"/>
    </inertial>
    <!-- <visual>
      <origin xyz="0.0 0.0 0.0" rpy="0.0 0.0 0.0"/>
      <geometry>
        <box size="0.030 0.018 0.009"/>
      </geometry>
      <material name="white"/>
    </visual> -->
    <collision>
      <origin xyz="0.0 0.0 0.0" rpy="0.0 0.0 0.0"/>
      <geometry>
        <box size="0.030 0.018 0.009"/>
      </geometry>
    </collision>
  </link>

  <joint name="joint_name" type="fixed">
    <origin xyz="-0.081 0.0 -0.004" rpy="0.0 0.0 0.0"/>
    <parent link="base_link"/>
    <child link="caster_link"/>
  </joint>

  <link name="camera_link">
    <inertial>
      <origin xyz="0.00043126 -3.048E-05 -8.6558E-05" rpy="0 0 0" />
      <mass value="0.0011135" />
      <inertia ixx="9.1087E-08" ixy="4.8461E-11" ixz="-3.8057E-09" iyy="5.1629E-08" iyz="3.3103E-10" izz="4.3465E-08" />
    </inertial>
    <visual>
      <origin xyz="0 0 0" rpy="0 0 0" />
      <geometry>
        <mesh filename="package://rider_description/meshes/camera_link.STL" />
      </geometry>
      <material name="grey"/>
    </visual>
    <collision>
      <origin xyz="0 0 0" rpy="0 0 0" />
      <geometry>
        <mesh filename="package://rider_description/meshes/camera_link.STL" />
      </geometry>
    </collision>
  </link>

  <joint name="camera_joint" type="fixed">
    <origin xyz="0.0347 0 0.1245" rpy="0 0 0" />
    <parent link="base_link" />
    <child link="camera_link" />
    <axis xyz="0 0 0" />
  </joint>

  <link name="imu_link"/>

  <joint name="imu_joint" type="fixed">
    <origin xyz="-0.032 0.0 0.058" rpy="0.0 0.0 0.0"/>
    <parent link="base_link"/>
    <child link="imu_link"/>
  </joint>

  <link name="lds_link">
    <inertial>
      <origin xyz="0.027313 -0.00023843 -0.092599" rpy="0 0 0" />
      <mass value="0.77199" />
      <inertia ixx="0.0026616" ixy="6.4059E-06" ixz="0.00012425" iyy="0.0022371" iyz="4.3265E-06" izz="0.0023602" />
    </inertial>
    <visual>
      <origin xyz="0 0 0" rpy="0 0 0" />
      <geometry>
        <mesh filename="package://rider_description/meshes/lds_link.STL" />
      </geometry>
      <material name="grey"/>
    </visual>
    <collision>
      <origin xyz="0 0 0" rpy="0 0 0" />
      <geometry>
        <mesh filename="package://rider_description/meshes/lds_link.STL" />
      </geometry>
    </collision>
  </link>

  <joint name="lds_joint" type="fixed">
    <origin xyz="-0.054 0 0.142" rpy="0 0 0" />
    <parent link="base_link" />
    <child link="lds_link" />
    <axis xyz="0 0 0" />
  </joint>
</robot>
